<?xml version="1.0" ?>
<sdf version="1.10">
  <model name='service_robot' canonical_link='base_link'>

    <!-- BASE LINK (chassis) -->
    <link name='base_link'>
      <pose relative_to='__model__'>0 0 0 0 0 0</pose>
      <inertial>
        <mass>5.0</mass>
        <inertia>
          <ixx>0.1042</ixx>
          <iyy>0.1875</iyy>
          <izz>0.2167</izz>
          <ixy>0</ixy><ixz>0</ixz><iyz>0</iyz>
        </inertia>
      </inertial>
      <visual name='chassis_visual'>
        <geometry><box><size>0.6 0.4 0.3</size></box></geometry>
        <material>
          <ambient>0.2 0.2 0.8 1</ambient>
          <diffuse>0.2 0.2 0.8 1</diffuse>
          <specular>0.3 0.3 0.3 1</specular>
        </material>
      </visual>
      <collision name='chassis_collision'>
        <geometry><box><size>0.6 0.4 0.3</size></box></geometry>
      </collision>

      <!-- LIDAR SENSOR -->
      <sensor name='gpu_lidar' type='gpu_lidar'>
        <gz_frame_id>lidar_link</gz_frame_id>
        <pose>0 0 0.2 0 0 0</pose>
        <topic>scan</topic>
        <update_rate>10</update_rate>
        <always_on>1</always_on>
        <visualize>true</visualize>
        <ray>
          <scan>
            <horizontal>
              <samples>640</samples>
              <resolution>1</resolution>
              <min_angle>-2.35619</min_angle>
              <max_angle>2.35619</max_angle>
            </horizontal>
            <vertical>
              <samples>1</samples>
              <resolution>0.01</resolution>
              <min_angle>0</min_angle>
              <max_angle>0</max_angle>
            </vertical>
          </scan>
          <range>
            <min>0.08</min>
            <max>10.0</max>
            <resolution>0.01</resolution>
          </range>
        </ray>
      </sensor>

      <!-- CAMERA SENSOR (front-facing) -->
      <sensor name='front_camera' type='camera'>
        <gz_frame_id>camera_link</gz_frame_id>
        <pose>0.3 0 0.05 0 0 0</pose>
        <topic>camera/image_raw</topic>
        <update_rate>15</update_rate>
        <always_on>1</always_on>
        <camera>
          <horizontal_fov>1.05</horizontal_fov>
          <image>
            <width>640</width>
            <height>480</height>
            <format>R8G8B8</format>
          </image>
          <clip>
            <near>0.1</near>
            <far>100</far>
          </clip>
        </camera>
      </sensor>

      <!-- IMU SENSOR -->
      <sensor name='imu_sensor' type='imu'>
        <gz_frame_id>imu_link</gz_frame_id>
        <pose>0 0 0 0 0 0</pose>
        <topic>imu</topic>
        <update_rate>50</update_rate>
        <always_on>1</always_on>
      </sensor>
    </link>

    <!-- LEFT WHEEL -->
    <link name='left_wheel'>
      <pose relative_to='base_link'>-0.05 0.23 -0.15 -1.5707963 0 0</pose>
      <inertial>
        <mass>0.5</mass>
        <inertia>
          <ixx>0.00135</ixx>
          <iyy>0.00135</iyy>
          <izz>0.0025</izz>
          <ixy>0</ixy><ixz>0</ixz><iyz>0</iyz>
        </inertia>
      </inertial>
      <visual name='left_wheel_visual'>
        <geometry><cylinder><radius>0.1</radius><length>0.05</length></cylinder></geometry>
        <material>
          <ambient>0.1 0.1 0.1 1</ambient>
          <diffuse>0.1 0.1 0.1 1</diffuse>
          <specular>0.1 0.1 0.1 1</specular>
        </material>
      </visual>
      <collision name='left_wheel_collision'>
        <geometry><cylinder><radius>0.1</radius><length>0.05</length></cylinder></geometry>
      </collision>
    </link>

    <!-- RIGHT WHEEL -->
    <link name='right_wheel'>
      <pose relative_to='base_link'>-0.05 -0.23 -0.15 -1.5707963 0 0</pose>
      <inertial>
        <mass>0.5</mass>
        <inertia>
          <ixx>0.00135</ixx>
          <iyy>0.00135</iyy>
          <izz>0.0025</izz>
          <ixy>0</ixy><ixz>0</ixz><iyz>0</iyz>
        </inertia>
      </inertial>
      <visual name='right_wheel_visual'>
        <geometry><cylinder><radius>0.1</radius><length>0.05</length></cylinder></geometry>
        <material>
          <ambient>0.1 0.1 0.1 1</ambient>
          <diffuse>0.1 0.1 0.1 1</diffuse>
          <specular>0.1 0.1 0.1 1</specular>
        </material>
      </visual>
      <collision name='right_wheel_collision'>
        <geometry><cylinder><radius>0.1</radius><length>0.05</length></cylinder></geometry>
      </collision>
    </link>

    <!-- CASTER WHEEL -->
    <link name='caster'>
      <pose relative_to='base_link'>0.25 0 -0.20 0 0 0</pose>
      <inertial>
        <mass>0.1</mass>
        <inertia>
          <ixx>0.0001</ixx>
          <iyy>0.0001</iyy>
          <izz>0.0001</izz>
          <ixy>0</ixy><ixz>0</ixz><iyz>0</iyz>
        </inertia>
      </inertial>
      <visual name='caster_visual'>
        <geometry><sphere><radius>0.05</radius></sphere></geometry>
        <material>
          <ambient>0.5 0.5 0.5 1</ambient>
          <diffuse>0.5 0.5 0.5 1</diffuse>
          <specular>0.5 0.5 0.5 1</specular>
        </material>
      </visual>
      <collision name='caster_collision'>
        <geometry><sphere><radius>0.05</radius></sphere></geometry>
      </collision>
    </link>

    <!-- JOINTS -->
    <joint name='left_wheel_joint' type='revolute'>
      <pose relative_to='left_wheel'/>
      <parent>base_link</parent>
      <child>left_wheel</child>
      <axis>
        <xyz expressed_in='__model__'>0 1 0</xyz>
        <limit>
          <lower>-1.79769e+308</lower>
          <upper>1.79769e+308</upper>
        </limit>
      </axis>
    </joint>

    <joint name='right_wheel_joint' type='revolute'>
      <pose relative_to='right_wheel'/>
      <parent>base_link</parent>
      <child>right_wheel</child>
      <axis>
        <xyz expressed_in='__model__'>0 1 0</xyz>
        <limit>
          <lower>-1.79769e+308</lower>
          <upper>1.79769e+308</upper>
        </limit>
      </axis>
    </joint>

    <joint name='caster_joint' type='ball'>
      <parent>base_link</parent>
      <child>caster</child>
    </joint>

    <!-- DIFFERENTIAL DRIVE PLUGIN -->
    <plugin
      filename="gz-sim-diff-drive-system"
      name="gz::sim::systems::DiffDrive">
      <left_joint>left_wheel_joint</left_joint>
      <right_joint>right_wheel_joint</right_joint>
      <wheel_separation>0.46</wheel_separation>
      <wheel_radius>0.1</wheel_radius>
      <odom_publish_frequency>30</odom_publish_frequency>
      <topic>cmd_vel</topic>
      <odom_topic>odom</odom_topic>
      <frame_id>odom</frame_id>
      <child_frame_id>base_link</child_frame_id>
      <tf_topic>tf</tf_topic>
    </plugin>

    <!-- JOINT STATE PUBLISHER -->
    <plugin
      filename="gz-sim-joint-state-publisher-system"
      name="gz::sim::systems::JointStatePublisher">
      <publish_rate>50</publish_rate>
    </plugin>

  </model>
</sdf>
